<sdf version='1.9'>
  <model name='arm'>
    <link name='dummy'>
      <inertial>
        <pose>-0.0420894636209823 -0.0119430230768063 0.014020548545619 0 0 0</pose>
        <mass>2.9852104670099702</mass>
        <inertia>
          <ixx>0.0175339728289488</ixx>
          <ixy>1.134383821050486e-19</ixy>
          <ixz>-1.1185181677560269e-20</ixz>
          <iyy>0.015905081715852299</iyy>
          <iyz>1.0511170183766749e-18</iyz>
          <izz>0.033340805189063003</izz>
        </inertia>
      </inertial>
      <collision name='dummy_fixed_joint_lump__base_link_collision'>
        <pose>0 0 0 0 0 0</pose>
        <geometry>
          <mesh>
            <scale>1 1 1</scale>
            <uri>model://meshes/base.STL</uri>
          </mesh>
        </geometry>
      </collision>
      <visual name='dummy_fixed_joint_lump__base_link_visual'>
        <pose>0 0 0 0 0 0</pose>
        <geometry>
          <mesh>
            <scale>1 1 1</scale>
            <uri>model://meshes/base.STL</uri>
          </mesh>
        </geometry>
        <material>
          <diffuse>1 1 1 1</diffuse>
          <ambient>1 1 1 1</ambient>
        </material>
      </visual>
    </link>
    <joint name='base_yaw_joint' type='revolute'>
      <pose relative_to='dummy'>-0.0420894636209815 -0.0119616169931191 0.0182598424192986 1.5707963267949 4.111543425206352e-17 1.05545161052463</pose>
      <parent>dummy</parent>
      <child>shoulder_link</child>
      <axis>
        <xyz>0 1 0</xyz>
        <limit>
          <lower>-3.1415926535897931</lower>
          <upper>3.1415926535897931</upper>
          <effort>1000</effort>
          <velocity>2.5</velocity>
        </limit>
        <dynamics>
          <spring_reference>0</spring_reference>
          <spring_stiffness>0</spring_stiffness>
        </dynamics>
      </axis>
    </joint>
    <link name='shoulder_link'>
      <pose relative_to='base_yaw_joint'>0 0 0 0 0 0</pose>
      <inertial>
        <pose>0.00527918694960809 0.07748199168015781 -0.0133622294690042 0 0 0</pose>
        <mass>4.5425843846421703</mass>
        <inertia>
          <ixx>0.0149524360381011</ixx>
          <ixy>1.05243789551392e-08</ixy>
          <ixz>-0.0017524703987240699</ixz>
          <iyy>0.0097049330132567002</iyy>
          <iyz>-6.4244674545168101e-09</iyz>
          <izz>0.012850990161083301</izz>
        </inertia>
      </inertial>
      <collision name='shoulder_link_collision'>
        <pose>0 0 0 0 0 0</pose>
        <geometry>
          <mesh>
            <scale>1 1 1</scale>
            <uri>model://arm/description/meshes/shoulder.STL</uri>
          </mesh>
        </geometry>
      </collision>
      <visual name='shoulder_link_visual'>
        <pose>0 0 0 0 0 0</pose>
        <geometry>
          <mesh>
            <scale>1 1 1</scale>
            <uri>model://arm/description/meshes/shoulder.STL</uri>
          </mesh>
        </geometry>
        <material>
          <diffuse>1 1 1 1</diffuse>
          <ambient>1 1 1 1</ambient>
        </material>
      </visual>
    </link>
    <joint name='shoulder_pitch_joint' type='revolute'>
      <pose relative_to='shoulder_link'>-0.0357971138440272 0.108175 0.00906194434350591 2.47061567686307 0.5153447162702681 -2.219503101805639e-19</pose>
      <parent>shoulder_link</parent>
      <child>bicep_link</child>
      <axis>
        <xyz>-1 0 0</xyz>
        <limit>
          <lower>-3.1415926535897931</lower>
          <upper>3.1415926535897931</upper>
          <effort>1000</effort>
          <velocity>2.5</velocity>
        </limit>
        <dynamics>
          <spring_reference>0</spring_reference>
          <spring_stiffness>0</spring_stiffness>
        </dynamics>
      </axis>
    </joint>
    <link name='bicep_link'>
      <pose relative_to='shoulder_pitch_joint'>0 0 0 0 0 0</pose>
      <inertial>
        <pose>-0.0416416588937773 -7.41489180611232e-08 -0.48063013151933 0 0 0</pose>
        <mass>4.2115739701460697</mass>
        <inertia>
          <ixx>0.026518336848638201</ixx>
          <ixy>1.2339772092184e-08</ixy>
          <ixz>-8.0388083234103e-06</ixz>
          <iyy>0.023824167896963601</iyy>
          <iyz>1.47058893537003e-08</iyz>
          <izz>0.00481440620919812</izz>
        </inertia>
      </inertial>
      <collision name='bicep_link_collision'>
        <pose>0 0 0 0 0 0</pose>
        <geometry>
          <mesh>
            <scale>1 1 1</scale>
            <uri>model://arm/description/meshes/bicep.STL</uri>
          </mesh>
        </geometry>
      </collision>
      <visual name='bicep_link_visual'>
        <pose>0 0 0 0 0 0</pose>
        <geometry>
          <mesh>
            <scale>1 1 1</scale>
            <uri>model://arm/description/meshes/bicep.STL</uri>
          </mesh>
        </geometry>
        <material>
          <diffuse>0.661765 0.686275 0.686275 1</diffuse>
          <ambient>0.661765 0.686275 0.686275 1</ambient>
        </material>
      </visual>
    </link>
    <joint name='elbow_pitch_joint' type='revolute'>
      <pose relative_to='bicep_link'>0.0030875 0 -0.58189 0.51635 7.195088970893212e-23 -3.141585307179587</pose>
      <parent>bicep_link</parent>
      <child>forearm_link</child>
      <axis>
        <xyz>-1 0 0</xyz>
        <limit>
          <lower>-3.1415926535897931</lower>
          <upper>3.1415926535897931</upper>
          <effort>1000</effort>
          <velocity>2.5</velocity>
        </limit>
        <dynamics>
          <spring_reference>0</spring_reference>
          <spring_stiffness>0</spring_stiffness>
        </dynamics>
      </axis>
    </joint>
    <link name='forearm_link'>
      <pose relative_to='elbow_pitch_joint'>0 0 0 0 0 0</pose>
      <inertial>
        <pose>-0.0433904621274588 4.81371441699019e-06 0.483997979293337 0 0 0</pose>
        <mass>4.35871818699448</mass>
        <inertia>
          <ixx>0.0266896327168114</ixx>
          <ixy>1.5431184182739501e-07</ixy>
          <ixz>6.6123138623610104e-06</ixz>
          <iyy>0.023915444728424998</iyy>
          <iyz>-7.15857024670289e-07</iyz>
          <izz>0.0049123020620024703</izz>
        </inertia>
      </inertial>
      <collision name='forearm_link_collision'>
        <pose>0 0 0 0 0 0</pose>
        <geometry>
          <mesh>
            <scale>1 1 1</scale>
            <uri>model://arm/description/meshes/forearm.STL</uri>
          </mesh>
        </geometry>
      </collision>
      <visual name='forearm_link_visual'>
        <pose>0 0 0 0 0 0</pose>
        <geometry>
          <mesh>
            <scale>1 1 1</scale>
            <uri>model://arm/description/meshes/forearm.STL</uri>
          </mesh>
        </geometry>
        <material>
          <diffuse>1 1 1 1</diffuse>
          <ambient>1 1 1 1</ambient>
        </material>
      </visual>
    </link>
    <joint name='wrist_pitch_joint' type='revolute'>
      <pose relative_to='forearm_link'>0 0 0.581887499995086 1.29896997033974 -0.262305000585875 2.39226953786024</pose>
      <parent>forearm_link</parent>
      <child>wrist_pitch_link</child>
      <axis>
        <xyz>-0.707107 0 0.707107</xyz>
        <limit>
          <lower>-3.1415926535897931</lower>
          <upper>3.1415926535897931</upper>
          <effort>1000</effort>
          <velocity>2.5</velocity>
        </limit>
        <dynamics>
          <spring_reference>0</spring_reference>
          <spring_stiffness>0</spring_stiffness>
        </dynamics>
      </axis>
    </joint>
    <link name='wrist_pitch_link'>
      <pose relative_to='wrist_pitch_joint'>0 0 0 0 0 0</pose>
      <inertial>
        <pose>-0.0455611950385227 -0.00725901759095772 0.009920706027536971 0 0 0</pose>
        <mass>0.86236150071067996</mass>
        <inertia>
          <ixx>0.0011893656582136101</ixx>
          <ixy>8.1104684346355098e-05</ixy>
          <ixz>-8.67557302037531e-05</ixz>
          <iyy>0.00086886430403283201</iyy>
          <iyz>8.97048798969999e-05</iyz>
          <izz>0.00119688008723862</izz>
        </inertia>
      </inertial>
      <collision name='wrist_pitch_link_collision'>
        <pose>0 0 0 0 0 0</pose>
        <geometry>
          <mesh>
            <scale>1 1 1</scale>
            <uri>model://arm/description/meshes/wrist pitch.STL</uri>
          </mesh>
        </geometry>
      </collision>
      <visual name='wrist_pitch_link_visual'>
        <pose>0 0 0 0 0 0</pose>
        <geometry>
          <mesh>
            <scale>1 1 1</scale>
            <uri>model://arm/description/meshes/wrist pitch.STL</uri>
          </mesh>
        </geometry>
        <material>
          <diffuse>1 1 1 1</diffuse>
          <ambient>1 1 1 1</ambient>
        </material>
      </visual>
    </link>
    <joint name='wrist_yaw_joint' type='revolute'>
      <pose relative_to='wrist_pitch_link'>0.017777291445819 0 -0.017777291445819 -0.9635975473601901 0.5184980410495011 0.9511944257736339</pose>
      <parent>wrist_pitch_link</parent>
      <child>wrist_yaw_link</child>
      <axis>
        <xyz>0.706887 0.017617 0.707107</xyz>
        <limit>
          <lower>-3.1415926535897931</lower>
          <upper>3.1415926535897931</upper>
          <effort>1000</effort>
          <velocity>2.5</velocity>
        </limit>
        <dynamics>
          <spring_reference>0</spring_reference>
          <spring_stiffness>0</spring_stiffness>
        </dynamics>
      </axis>
    </joint>
    <link name='wrist_yaw_link'>
      <pose relative_to='wrist_yaw_joint'>0 0 0 0 0 0</pose>
      <inertial>
        <pose>-0.00573736378208815 0.0709654882442483 0.08636231630849479 0 0 0</pose>
        <mass>0.35886867343887502</mass>
        <inertia>
          <ixx>0.00041430959860063902</ixx>
          <ixy>-9.2583446541486995e-06</ixy>
          <ixz>-1.42368460656332e-05</ixz>
          <iyy>0.00035655418795287199</iyy>
          <iyz>-1.7963681894808099e-08</iyz>
          <izz>0.00041349714164066201</izz>
        </inertia>
      </inertial>
      <collision name='wrist_yaw_link_collision'>
        <pose>0 0 0 0 0 0</pose>
        <geometry>
          <mesh>
            <scale>1 1 1</scale>
            <uri>model://arm/description/meshes/wrist yaw.STL</uri>
          </mesh>
        </geometry>
      </collision>
      <visual name='wrist_yaw_link_visual'>
        <pose>0 0 0 0 0 0</pose>
        <geometry>
          <mesh>
            <scale>1 1 1</scale>
            <uri>model://arm/description/meshes/wrist yaw.STL</uri>
          </mesh>
        </geometry>
        <material>
          <diffuse>1 1 1 1</diffuse>
          <ambient>1 1 1 1</ambient>
        </material>
      </visual>
    </link>
    <joint name='wrist_roll_joint' type='revolute'>
      <pose relative_to='wrist_yaw_link'>0.00632947155943084 0.272267270409697 0.1004658595574 -1.56931940382504 -0.8275470581813221 3.13950582346102</pose>
      <parent>wrist_yaw_link</parent>
      <child>wrist_roll_link</child>
      <axis>
        <xyz>0.000668 0.01766 -0.999844</xyz>
        <limit>
          <lower>-3.1415926535897931</lower>
          <upper>3.1415926535897931</upper>
          <effort>1000</effort>
          <velocity>2.5</velocity>
        </limit>
        <dynamics>
          <spring_reference>0</spring_reference>
          <spring_stiffness>0</spring_stiffness>
        </dynamics>
      </axis>
    </joint>
    <link name='wrist_roll_link'>
      <pose relative_to='wrist_roll_joint'>0 0 0 0 0 0</pose>
      <inertial>
        <pose>-0.00276942184890096 0.0187204574927389 0.0271220665563111 0 0 0</pose>
        <mass>0.57859407781531302</mass>
        <inertia>
          <ixx>0.00049174931542777004</ixx>
          <ixy>-3.3897062265723002e-06</ixy>
          <ixz>-1.18435403501392e-07</ixz>
          <iyy>0.00057218353360479195</iyy>
          <iyz>9.7840554837207992e-06</iyz>
          <izz>0.000301532531672388</izz>
        </inertia>
      </inertial>
      <collision name='wrist_roll_link_collision'>
        <pose>0 0 0 0 0 0</pose>
        <geometry>
          <mesh>
            <scale>1 1 1</scale>
            <uri>model://arm/description/meshes/wrist roll.STL</uri>
          </mesh>
        </geometry>
      </collision>
      <visual name='wrist_roll_link_visual'>
        <pose>0 0 0 0 0 0</pose>
        <geometry>
          <mesh>
            <scale>1 1 1</scale>
            <uri>model://arm/description/meshes/wrist roll.STL</uri>
          </mesh>
        </geometry>
        <material>
          <diffuse>0.941176 0.941176 0.941176 1</diffuse>
          <ambient>0.941176 0.941176 0.941176 1</ambient>
        </material>
      </visual>
    </link>
    <plugin name='ign_ros2_control::IgnitionROS2ControlPlugin' filename='ign_ros2_control-system'>
      <parameters>$(find arm)/config/arm_controller.yaml</parameters>
    </plugin>
    <frame name='dummy_joint' attached_to='dummy'>
      <pose>0 0 0 0 -0 0</pose>
    </frame>
    <frame name='base_link' attached_to='dummy_joint'/>
  </model>
</sdf>
