<robot name="ros2_drive_urdf">

  <link name="chassis">
    <inertial>
      <origin xyz="-0.00887504191546608 0.0454280414162516 -0.0207767269551461" rpy="0 0 0" />
      <mass value="43.2370874728493" />
      <inertia ixx="1.508630498225" ixy="-0.00302461371941334" ixz="0.000799866263484775" iyy="1.87554173268809" iyz="8.05813048835996E-05" izz="0.602015519267222" />
    </inertial>
    </link>
  <link name="left_suspension">
    <inertial>
      <origin xyz="0.172215376940955 -0.219926551052699 -0.490579186451289" rpy="0 0 0" />
      <mass value="11.9678875805757" />
      <inertia ixx="0.0520935457647714" ixy="-0.0017784858645164" ixz="2.78254531336256E-09" iyy="0.0549508980902833" iyz="1.04804950454143E-10" izz="0.096605677505146" />
    </inertial>
    </link>
  <joint name="left_rocker" type="continuous">
    <origin xyz="0 0 0" rpy="0 0 0" />
    <parent link="chassis" />
    <child link="left_suspension" />
    <axis xyz="0 0 1" />
  </joint>
  <link name="right_suspension">
    <inertial>
      <origin xyz="0.172215405427646 -0.219926487315361 0.449109338075975" rpy="0 0 0" />
      <mass value="11.9678638553643" />
      <inertia ixx="0.0520934514608789" ixy="-0.00177848524169037" ixz="-3.22986814176042E-09" iyy="0.0549508041969931" iyz="-6.07127116525645E-10" izz="0.0966055262754389" />
    </inertial>
    </link>
  <joint name="right_rocker" type="continuous">
    <origin xyz="0 0 0" rpy="0 0 0" />
    <parent link="chassis" />
    <child link="right_suspension" />
    <axis xyz="0 0 1" />
  </joint>
</robot>